in user code:

    File "C:\Users\Yoon\anaconda3\lib\site-packages\keras\engine\training.py", line 1845, in predict_function  *
        return step_function(self, iterator)
    File "C:\Users\Yoon\anaconda3\lib\site-packages\keras\engine\training.py", line 1834, in step_function  **
        outputs = model.distribute_strategy.run(run_step, args=(data,))
    File "C:\Users\Yoon\anaconda3\lib\site-packages\keras\engine\training.py", line 1823, in run_step  **
        outputs = model.predict_step(data)
    File "C:\Users\Yoon\anaconda3\lib\site-packages\keras\engine\training.py", line 1791, in predict_step
        return self(x, training=False)
    File "C:\Users\Yoon\anaconda3\lib\site-packages\keras\utils\traceback_utils.py", line 67, in error_handler
        raise e.with_traceback(filtered_tb) from None
    File "C:\Users\Yoon\anaconda3\lib\site-packages\keras\engine\input_spec.py", line 264, in assert_input_compatibility
        raise ValueError(f'Input {input_index} of layer "{layer_name}" is '

    ValueError: Input 0 of layer "sequential" is incompatible with the layer: expected shape=(None, 100), found shape=(None, 50)
